<mujoco model="ant">
  <compiler angle="degree" coordinate="local" inertiafromgeom="true" settotalmass="25755"/>
  <option integrator="RK4" timestep="0.005"/>
  <custom>
    <numeric data="0.0 0.0 0.55 1.0 0.0 0.0 0.0 0.0 1.0 0.0 -1.0 0.0 -1.0 0.0 1.0" name="init_qpos"/>
  </custom>
  <default>
    <joint armature="1" damping="1" limited="true"/>
    <geom conaffinity="0" condim="3" density="5.0" friction="1 0.5 0.5" margin="0.01" rgba="0.8 0.6 0.4 1" material="geom"/>
  </default>
    <asset>
        <texture name="monstertex" type="cube" file="monstertex.png" gridsize="3 4" gridlayout=".U..LDRB.F.."/>
        <texture type="skybox" builtin="gradient" rgb1=".1 .12 .15" rgb2="0 0 0" width="100" height="100"/>
        <texture builtin="checker" height="100" name="texplane" rgb1=".1 .1 .1" rgb2=".15 .15 0.15" type="2d" width="100"/>
        <material name="MatPlane" reflectance="0.5" shininess="1" specular="1" texrepeat="50 50" texture="texplane"/>
        <texture builtin="flat" height="1278" mark="cross" markrgb="1 1 1" name="texgeom" random="0.01" rgb1="0.8 0.6 0.4" rgb2="0.8 0.6 0.4" type="cube" width="127"/>
        <material name="monstermat" texture="monstertex" texuniform="true"/>
        <material name="geom" texture="texgeom" texuniform="true"/>
    </asset>
  <worldbody>
    <light cutoff="100" diffuse="1 1 1" dir="-0 0 -1.3" directional="true" exponent="1" pos="0 0 1.3" specular=".1 .1 .1"/>
    <geom conaffinity="1" condim="3" material="MatPlane" name="floor" pos="0 0 0" rgba="0.8 0.9 0.8 1" size="40 40 40" type="plane"/>
    <body name="torso" pos="0 0 0.6">
      <geom name="torso_geom" pos="0 0 0" size="0.25" type="sphere"/>
      <geom name="head" density="0.01" rgba="1.0 0.5 0.3 1" pos="0.4 0 0.25" size="0.25" type="sphere"/>
      <joint armature="0" damping="0" limited="false" margin="0.01" name="root" pos="0 0 0" type="free"/>
      <body name="front_left_leg" pos="0 0 0">
        <geom fromto="0.0 0.0 0.0 0.2 0.2 0.0" name="aux_1_geom" size="0.08" type="capsule"/>
        <body name="aux_1" pos="0.2 0.2 0">
          <joint axis="0 0 1" name="hip_1" pos="0.0 0.0 0.0" range="-30 30" type="hinge"/>
          <geom fromto="0.0 0.0 0.0 0.2 0.2 0.0" name="left_leg_geom" size="0.08" type="capsule"/>
          <body pos="0.2 0.2 0">
            <joint axis="-1 1 0" name="ankle_1" pos="0.0 0.0 0.0" range="30 70" type="hinge"/>
            <geom fromto="0.0 0.0 0.0 0.4 0.4 0.0" name="left_ankle_geom" size="0.08" type="capsule"/>
          </body>
        </body>
      </body>
      <body name="front_right_leg" pos="0 0 0">
        <geom fromto="0.0 0.0 0.0 -0.2 0.2 0.0" name="aux_2_geom" size="0.08" type="capsule"/>
        <body name="aux_2" pos="-0.2 0.2 0">
          <joint axis="0 0 1" name="hip_2" pos="0.0 0.0 0.0" range="-30 30" type="hinge"/>
          <geom fromto="0.0 0.0 0.0 -0.2 0.2 0.0" name="right_leg_geom" size="0.08" type="capsule"/>
          <body pos="-0.2 0.2 0">
            <joint axis="1 1 0" name="ankle_2" pos="0.0 0.0 0.0" range="-70 -30" type="hinge"/>
            <geom fromto="0.0 0.0 0.0 -0.4 0.4 0.0" name="right_ankle_geom" size="0.08" type="capsule"/>
          </body>
        </body>
      </body>
      <body name="back_leg" pos="0 0 0">
        <geom fromto="0.0 0.0 0.0 -0.2 -0.2 0.0" name="aux_3_geom" size="0.08" type="capsule"/>
        <body name="aux_3" pos="-0.2 -0.2 0">
          <joint axis="0 0 1" name="hip_3" pos="0.0 0.0 0.0" range="-30 30" type="hinge"/>
          <geom fromto="0.0 0.0 0.0 -0.2 -0.2 0.0" name="back_leg_geom" size="0.08" type="capsule"/>
          <body pos="-0.2 -0.2 0">
            <joint axis="-1 1 0" name="ankle_3" pos="0.0 0.0 0.0" range="-70 -30" type="hinge"/>
            <geom fromto="0.0 0.0 0.0 -0.4 -0.4 0.0" name="third_ankle_geom" size="0.08" type="capsule"/>
          </body>
        </body>
      </body>
      <body name="right_back_leg" pos="0 0 0">
        <geom fromto="0.0 0.0 0.0 0.2 -0.2 0.0" name="aux_4_geom" size="0.08" type="capsule"/>
        <body name="aux_4" pos="0.2 -0.2 0">
          <joint axis="0 0 1" name="hip_4" pos="0.0 0.0 0.0" range="-30 30" type="hinge"/>
          <geom fromto="0.0 0.0 0.0 0.2 -0.2 0.0" name="rightback_leg_geom" size="0.08" type="capsule"/>
          <body pos="0.2 -0.2 0">
            <joint axis="1 1 0" name="ankle_4" pos="0.0 0.0 0.0" range="30 70" type="hinge"/>
            <geom fromto="0.0 0.0 0.0 0.4 -0.4 0.0" name="fourth_ankle_geom" size="0.08" type="capsule"/>
          </body>
        </body>
      </body>
    </body>

    <geom pos="28 -3 0" conaffinity="1" rgba="0.9 0.9 0.9 1" size="35 0.3 5" type="box"/>
    <geom pos="28 40 0" conaffinity="1" rgba="0.9 0.9 0.9 1" size="35 0.3 5" type="box"/>
    <geom pos="-3 28 0" conaffinity="1" rgba="0.9 0.9 0.9 1" size="0.3 35 5" type="box"/>
    <geom pos="40 28 0" conaffinity="1" rgba="0.9 0.9 0.9 1" size="0.3 35 5" type="box"/>

    <!-- <geom pos="6 5 0" conaffinity="1" rgba="0.9 0.2 0.2 1" size="8 0.3 2" type="box"/> -->
    <geom pos="35 25 0" conaffinity="1" rgba="0.9 0.9 0.9 1" size="5 0.3 5" type="box"/>
    <!-- <geom pos="35 5 0" conaffinity="1" rgba="0.9 0.9 0.9 1" size="5 0.3 2" type="box"/> -->

    <!-- <geom pos="15 24 0" conaffinity="1" rgba="0.9 0.2 0.2 1" size="0.3 20 2" type="box"/> -->
    <geom pos="30 10 0" conaffinity="1" rgba="0.9 0.9 0.9 1" size="0.3 15 5" type="box"/>

    <!-- the monster -->
    <geom pos="0 20 0" conaffinity="0" contype="0" rgba="0.9 0.2 0.2 1" size="15 15 0.1" type="ellipsoid"/>
    <body name="monster" pos="0 0 0">
      <geom pos="0 0 1" material="monstermat" conaffinity="1" rgba="1 1 1 1" size="3 3 3" type="ellipsoid"/>
      <joint armature="0" axis="1 0 0" damping="0" limited="false" name="horiz" pos="0 0 0" stiffness="0" type="slide"/>
      <joint armature="0" axis="0 1 0" damping="0" limited="false" name="vert" pos="0 0 0" stiffness="0" type="slide"/>
    </body>

    <geom pos="38 38 3" conaffinity="1" rgba="0.2 0.9 0.2 1" size="1 1 0.3" type="box"/>

  </worldbody>
  <actuator>
    <motor ctrllimited="true" ctrlrange="-1.0 1.0" joint="hip_4" gear="150"/>
    <motor ctrllimited="true" ctrlrange="-1.0 1.0" joint="ankle_4" gear="150"/>
    <motor ctrllimited="true" ctrlrange="-1.0 1.0" joint="hip_1" gear="150"/>
    <motor ctrllimited="true" ctrlrange="-1.0 1.0" joint="ankle_1" gear="150"/>
    <motor ctrllimited="true" ctrlrange="-1.0 1.0" joint="hip_2" gear="150"/>
    <motor ctrllimited="true" ctrlrange="-1.0 1.0" joint="ankle_2" gear="150"/>
    <motor ctrllimited="true" ctrlrange="-1.0 1.0" joint="hip_3" gear="150"/>
    <motor ctrllimited="true" ctrlrange="-1.0 1.0" joint="ankle_3" gear="150"/>
  </actuator>
  <sensor>
    <jointpos name='pos_hip_1' joint='hip_1' />
    <jointpos name='pos_hip_2' joint='hip_2' />
    <jointpos name='pos_hip_3' joint='hip_3' />
    <jointpos name='pos_hip_4' joint='hip_4' />
    <jointpos name='pos_ankle_1' joint='ankle_1' />
    <jointpos name='pos_ankle_2' joint='ankle_2' />
    <jointpos name='pos_ankle_3' joint='ankle_3' />
    <jointpos name='pos_ankle_4' joint='ankle_4' />

    <jointvel name='vel_hip_1'   joint='hip_1' />
    <jointvel name='vel_hip_2'   joint='hip_2' />
    <jointvel name='vel_hip_3'   joint='hip_3' />
    <jointvel name='vel_hip_4'   joint='hip_4' />
    <jointvel name='vel_ankle_1' joint='ankle_1' />
    <jointvel name='vel_ankle_2' joint='ankle_2' />
    <jointvel name='vel_ankle_3' joint='ankle_3' />
    <jointvel name='vel_ankle_4' joint='ankle_4' />
  </sensor>
</mujoco>
